2022-03-14 14:13:07.124215: I tensorflow/stream_executor/platform/default/dso_loader.cc:53] Successfully opened dynamic library libcudart.so.11.0
2022-03-14 14:13:07.124216: I tensorflow/stream_executor/platform/default/dso_loader.cc:53] Successfully opened dynamic library libcudart.so.11.0
2022-03-14 14:13:07.148602: I tensorflow/stream_executor/platform/default/dso_loader.cc:53] Successfully opened dynamic library libcudart.so.11.0
2022-03-14 14:13:07.152589: I tensorflow/stream_executor/platform/default/dso_loader.cc:53] Successfully opened dynamic library libcudart.so.11.0
--------------------------------------------------------------------------
WARNING: There was an error initializing an OpenFabrics device.

  Local host:   dl020
  Local device: mlx4_0
--------------------------------------------------------------------------
2022-03-14 14:13:08.249308: I tensorflow/stream_executor/platform/default/dso_loader.cc:53] Successfully opened dynamic library libcuda.so.1
2022-03-14 14:13:08.249305: I tensorflow/stream_executor/platform/default/dso_loader.cc:53] Successfully opened dynamic library libcuda.so.1
2022-03-14 14:13:08.249879: I tensorflow/stream_executor/platform/default/dso_loader.cc:53] Successfully opened dynamic library libcuda.so.1
2022-03-14 14:13:08.249867: I tensorflow/stream_executor/platform/default/dso_loader.cc:53] Successfully opened dynamic library libcuda.so.1
2022-03-14 14:13:09.865425: I tensorflow/core/common_runtime/gpu/gpu_device.cc:1733] Found device 0 with properties: 
pciBusID: 0000:02:00.0 name: NVIDIA TITAN Xp computeCapability: 6.1
coreClock: 1.582GHz coreCount: 30 deviceMemorySize: 11.91GiB deviceMemoryBandwidth: 510.07GiB/s
2022-03-14 14:13:09.865998: I tensorflow/core/common_runtime/gpu/gpu_device.cc:1733] Found device 0 with properties: 
pciBusID: 0000:02:00.0 name: NVIDIA TITAN Xp computeCapability: 6.1
coreClock: 1.582GHz coreCount: 30 deviceMemorySize: 11.91GiB deviceMemoryBandwidth: 510.07GiB/s
2022-03-14 14:13:09.881868: I tensorflow/core/common_runtime/gpu/gpu_device.cc:1733] Found device 0 with properties: 
pciBusID: 0000:02:00.0 name: NVIDIA TITAN Xp computeCapability: 6.1
coreClock: 1.582GHz coreCount: 30 deviceMemorySize: 11.91GiB deviceMemoryBandwidth: 510.07GiB/s
2022-03-14 14:13:09.883619: I tensorflow/core/common_runtime/gpu/gpu_device.cc:1733] Found device 1 with properties: 
pciBusID: 0000:04:00.0 name: NVIDIA TITAN Xp computeCapability: 6.1
coreClock: 1.582GHz coreCount: 30 deviceMemorySize: 11.91GiB deviceMemoryBandwidth: 510.07GiB/s
2022-03-14 14:13:09.884206: I tensorflow/core/common_runtime/gpu/gpu_device.cc:1733] Found device 1 with properties: 
pciBusID: 0000:04:00.0 name: NVIDIA TITAN Xp computeCapability: 6.1
coreClock: 1.582GHz coreCount: 30 deviceMemorySize: 11.91GiB deviceMemoryBandwidth: 510.07GiB/s
2022-03-14 14:13:09.887344: I tensorflow/core/common_runtime/gpu/gpu_device.cc:1733] Found device 1 with properties: 
pciBusID: 0000:04:00.0 name: NVIDIA TITAN Xp computeCapability: 6.1
coreClock: 1.582GHz coreCount: 30 deviceMemorySize: 11.91GiB deviceMemoryBandwidth: 510.07GiB/s
2022-03-14 14:13:09.889090: I tensorflow/core/common_runtime/gpu/gpu_device.cc:1733] Found device 2 with properties: 
pciBusID: 0000:83:00.0 name: NVIDIA TITAN Xp computeCapability: 6.1
coreClock: 1.582GHz coreCount: 30 deviceMemorySize: 11.91GiB deviceMemoryBandwidth: 510.07GiB/s
2022-03-14 14:13:09.890840: I tensorflow/core/common_runtime/gpu/gpu_device.cc:1733] Found device 2 with properties: 
pciBusID: 0000:83:00.0 name: NVIDIA TITAN Xp computeCapability: 6.1
coreClock: 1.582GHz coreCount: 30 deviceMemorySize: 11.91GiB deviceMemoryBandwidth: 510.07GiB/s
2022-03-14 14:13:09.892555: I tensorflow/core/common_runtime/gpu/gpu_device.cc:1733] Found device 0 with properties: 
pciBusID: 0000:02:00.0 name: NVIDIA TITAN Xp computeCapability: 6.1
coreClock: 1.582GHz coreCount: 30 deviceMemorySize: 11.91GiB deviceMemoryBandwidth: 510.07GiB/s
2022-03-14 14:13:09.893909: I tensorflow/core/common_runtime/gpu/gpu_device.cc:1733] Found device 2 with properties: 
pciBusID: 0000:83:00.0 name: NVIDIA TITAN Xp computeCapability: 6.1
coreClock: 1.582GHz coreCount: 30 deviceMemorySize: 11.91GiB deviceMemoryBandwidth: 510.07GiB/s
2022-03-14 14:13:09.899063: I tensorflow/core/common_runtime/gpu/gpu_device.cc:1733] Found device 3 with properties: 
pciBusID: 0000:84:00.0 name: NVIDIA TITAN Xp computeCapability: 6.1
coreClock: 1.582GHz coreCount: 30 deviceMemorySize: 11.91GiB deviceMemoryBandwidth: 510.07GiB/s
2022-03-14 14:13:09.899120: I tensorflow/stream_executor/platform/default/dso_loader.cc:53] Successfully opened dynamic library libcudart.so.11.0
2022-03-14 14:13:09.900561: I tensorflow/core/common_runtime/gpu/gpu_device.cc:1733] Found device 3 with properties: 
pciBusID: 0000:84:00.0 name: NVIDIA TITAN Xp computeCapability: 6.1
coreClock: 1.582GHz coreCount: 30 deviceMemorySize: 11.91GiB deviceMemoryBandwidth: 510.07GiB/s
2022-03-14 14:13:09.900610: I tensorflow/stream_executor/platform/default/dso_loader.cc:53] Successfully opened dynamic library libcudart.so.11.0
2022-03-14 14:13:09.901879: I tensorflow/core/common_runtime/gpu/gpu_device.cc:1733] Found device 1 with properties: 
pciBusID: 0000:04:00.0 name: NVIDIA TITAN Xp computeCapability: 6.1
coreClock: 1.582GHz coreCount: 30 deviceMemorySize: 11.91GiB deviceMemoryBandwidth: 510.07GiB/s
2022-03-14 14:13:09.902042: I tensorflow/core/common_runtime/gpu/gpu_device.cc:1733] Found device 3 with properties: 
pciBusID: 0000:84:00.0 name: NVIDIA TITAN Xp computeCapability: 6.1
coreClock: 1.582GHz coreCount: 30 deviceMemorySize: 11.91GiB deviceMemoryBandwidth: 510.07GiB/s
2022-03-14 14:13:09.902100: I tensorflow/stream_executor/platform/default/dso_loader.cc:53] Successfully opened dynamic library libcudart.so.11.0
2022-03-14 14:13:09.903449: I tensorflow/core/common_runtime/gpu/gpu_device.cc:1733] Found device 2 with properties: 
pciBusID: 0000:83:00.0 name: NVIDIA TITAN Xp computeCapability: 6.1
coreClock: 1.582GHz coreCount: 30 deviceMemorySize: 11.91GiB deviceMemoryBandwidth: 510.07GiB/s
2022-03-14 14:13:09.904972: I tensorflow/core/common_runtime/gpu/gpu_device.cc:1733] Found device 3 with properties: 
pciBusID: 0000:84:00.0 name: NVIDIA TITAN Xp computeCapability: 6.1
coreClock: 1.582GHz coreCount: 30 deviceMemorySize: 11.91GiB deviceMemoryBandwidth: 510.07GiB/s
2022-03-14 14:13:09.905019: I tensorflow/stream_executor/platform/default/dso_loader.cc:53] Successfully opened dynamic library libcudart.so.11.0
2022-03-14 14:13:09.906740: I tensorflow/stream_executor/platform/default/dso_loader.cc:53] Successfully opened dynamic library libcublas.so.11
2022-03-14 14:13:09.906791: I tensorflow/stream_executor/platform/default/dso_loader.cc:53] Successfully opened dynamic library libcublasLt.so.11
2022-03-14 14:13:09.908888: I tensorflow/stream_executor/platform/default/dso_loader.cc:53] Successfully opened dynamic library libcublas.so.11
2022-03-14 14:13:09.908958: I tensorflow/stream_executor/platform/default/dso_loader.cc:53] Successfully opened dynamic library libcublasLt.so.11
2022-03-14 14:13:09.909159: I tensorflow/stream_executor/platform/default/dso_loader.cc:53] Successfully opened dynamic library libcufft.so.10
2022-03-14 14:13:09.909372: I tensorflow/stream_executor/platform/default/dso_loader.cc:53] Successfully opened dynamic library libcublas.so.11
2022-03-14 14:13:09.909454: I tensorflow/stream_executor/platform/default/dso_loader.cc:53] Successfully opened dynamic library libcurand.so.10
2022-03-14 14:13:09.909468: I tensorflow/stream_executor/platform/default/dso_loader.cc:53] Successfully opened dynamic library libcublasLt.so.11
2022-03-14 14:13:09.910107: I tensorflow/stream_executor/platform/default/dso_loader.cc:53] Successfully opened dynamic library libcusolver.so.11
2022-03-14 14:13:09.911124: I tensorflow/stream_executor/platform/default/dso_loader.cc:53] Successfully opened dynamic library libcusparse.so.11
2022-03-14 14:13:09.911267: I tensorflow/stream_executor/platform/default/dso_loader.cc:53] Successfully opened dynamic library libcudnn.so.8
2022-03-14 14:13:09.911292: I tensorflow/stream_executor/platform/default/dso_loader.cc:53] Successfully opened dynamic library libcublas.so.11
2022-03-14 14:13:09.911352: I tensorflow/stream_executor/platform/default/dso_loader.cc:53] Successfully opened dynamic library libcublasLt.so.11
2022-03-14 14:13:09.911782: I tensorflow/stream_executor/platform/default/dso_loader.cc:53] Successfully opened dynamic library libcufft.so.10
2022-03-14 14:13:09.912038: I tensorflow/stream_executor/platform/default/dso_loader.cc:53] Successfully opened dynamic library libcurand.so.10
2022-03-14 14:13:09.912081: I tensorflow/stream_executor/platform/default/dso_loader.cc:53] Successfully opened dynamic library libcufft.so.10
2022-03-14 14:13:09.912450: I tensorflow/stream_executor/platform/default/dso_loader.cc:53] Successfully opened dynamic library libcurand.so.10
2022-03-14 14:13:09.912562: I tensorflow/stream_executor/platform/default/dso_loader.cc:53] Successfully opened dynamic library libcusolver.so.11
2022-03-14 14:13:09.913267: I tensorflow/stream_executor/platform/default/dso_loader.cc:53] Successfully opened dynamic library libcusolver.so.11
2022-03-14 14:13:09.913473: I tensorflow/stream_executor/platform/default/dso_loader.cc:53] Successfully opened dynamic library libcusparse.so.11
2022-03-14 14:13:09.913600: I tensorflow/stream_executor/platform/default/dso_loader.cc:53] Successfully opened dynamic library libcudnn.so.8
2022-03-14 14:13:09.914598: I tensorflow/stream_executor/platform/default/dso_loader.cc:53] Successfully opened dynamic library libcusparse.so.11
2022-03-14 14:13:09.914692: I tensorflow/stream_executor/platform/default/dso_loader.cc:53] Successfully opened dynamic library libcufft.so.10
2022-03-14 14:13:09.914781: I tensorflow/stream_executor/platform/default/dso_loader.cc:53] Successfully opened dynamic library libcudnn.so.8
2022-03-14 14:13:09.915043: I tensorflow/stream_executor/platform/default/dso_loader.cc:53] Successfully opened dynamic library libcurand.so.10
2022-03-14 14:13:09.915879: I tensorflow/stream_executor/platform/default/dso_loader.cc:53] Successfully opened dynamic library libcusolver.so.11
2022-03-14 14:13:09.917297: I tensorflow/stream_executor/platform/default/dso_loader.cc:53] Successfully opened dynamic library libcusparse.so.11
2022-03-14 14:13:09.917479: I tensorflow/stream_executor/platform/default/dso_loader.cc:53] Successfully opened dynamic library libcudnn.so.8
2022-03-14 14:13:09.927541: I tensorflow/core/common_runtime/gpu/gpu_device.cc:1871] Adding visible gpu devices: 0, 1, 2, 3
Downloading data from https://people.eecs.berkeley.edu/~tinghuiz/projects/pix2pix/datasets/facades.tar.gz
2022-03-14 14:13:09.947720: I tensorflow/core/common_runtime/gpu/gpu_device.cc:1871] Adding visible gpu devices: 0, 1, 2, 3
Downloading data from https://people.eecs.berkeley.edu/~tinghuiz/projects/pix2pix/datasets/facades.tar.gz
2022-03-14 14:13:09.950070: I tensorflow/core/common_runtime/gpu/gpu_device.cc:1871] Adding visible gpu devices: 0, 1, 2, 3
2022-03-14 14:13:09.951420: I tensorflow/core/common_runtime/gpu/gpu_device.cc:1871] Adding visible gpu devices: 0, 1, 2, 3
Downloading data from https://people.eecs.berkeley.edu/~tinghuiz/projects/pix2pix/datasets/facades.tar.gz
Downloading data from https://people.eecs.berkeley.edu/~tinghuiz/projects/pix2pix/datasets/facades.tar.gz
Traceback (most recent call last):
  File "/data/plrg/ve/lib/python3.8/site-packages/tensorflow/python/keras/utils/data_utils.py", line 258, in get_file
    urlretrieve(origin, fpath, dl_progress)
  File "/usr/lib/python3.8/urllib/request.py", line 247, in urlretrieve
    with contextlib.closing(urlopen(url, data)) as fp:
  File "/usr/lib/python3.8/urllib/request.py", line 222, in urlopen
    return opener.open(url, data, timeout)
  File "/usr/lib/python3.8/urllib/request.py", line 531, in open
    response = meth(req, response)
  File "/usr/lib/python3.8/urllib/request.py", line 640, in http_response
    response = self.parent.error(
  File "/usr/lib/python3.8/urllib/request.py", line 563, in error
    result = self._call_chain(*args)
  File "/usr/lib/python3.8/urllib/request.py", line 502, in _call_chain
    result = func(*args)
  File "/usr/lib/python3.8/urllib/request.py", line 755, in http_error_302
    return self.parent.open(new, timeout=req.timeout)
  File "/usr/lib/python3.8/urllib/request.py", line 531, in open
    response = meth(req, response)
  File "/usr/lib/python3.8/urllib/request.py", line 640, in http_response
    response = self.parent.error(
  File "/usr/lib/python3.8/urllib/request.py", line 569, in error
    return self._call_chain(*args)
  File "/usr/lib/python3.8/urllib/request.py", line 502, in _call_chain
    result = func(*args)
  File "/usr/lib/python3.8/urllib/request.py", line 649, in http_error_default
    raise HTTPError(req.full_url, code, msg, hdrs, fp)
urllib.error.HTTPError: HTTP Error 404: Not Found

During handling of the above exception, another exception occurred:

Traceback (most recent call last):
  File "main.py", line 23, in <module>
    path_to_zip = keras.utils.get_file("facades.tar.gz", cache_subdir=os.path.abspath(".", ), origin="https://people.eecs.berkeley.edu/~tinghuiz/projects/pix2pix/datasets/facades.tar.gz", extract=True, )
  File "/data/plrg/ve/lib/python3.8/site-packages/tensorflow/python/keras/utils/data_utils.py", line 260, in get_file
    raise Exception(error_msg.format(origin, e.code, e.msg))
Exception: URL fetch failure on https://people.eecs.berkeley.edu/~tinghuiz/projects/pix2pix/datasets/facades.tar.gz: 404 -- Not Found
Traceback (most recent call last):
  File "/data/plrg/ve/lib/python3.8/site-packages/tensorflow/python/keras/utils/data_utils.py", line 258, in get_file
    urlretrieve(origin, fpath, dl_progress)
  File "/usr/lib/python3.8/urllib/request.py", line 247, in urlretrieve
    with contextlib.closing(urlopen(url, data)) as fp:
  File "/usr/lib/python3.8/urllib/request.py", line 222, in urlopen
    return opener.open(url, data, timeout)
  File "/usr/lib/python3.8/urllib/request.py", line 531, in open
    response = meth(req, response)
  File "/usr/lib/python3.8/urllib/request.py", line 640, in http_response
    response = self.parent.error(
  File "/usr/lib/python3.8/urllib/request.py", line 563, in error
    result = self._call_chain(*args)
  File "/usr/lib/python3.8/urllib/request.py", line 502, in _call_chain
    result = func(*args)
  File "/usr/lib/python3.8/urllib/request.py", line 755, in http_error_302
    return self.parent.open(new, timeout=req.timeout)
  File "/usr/lib/python3.8/urllib/request.py", line 531, in open
    response = meth(req, response)
  File "/usr/lib/python3.8/urllib/request.py", line 640, in http_response
    response = self.parent.error(
  File "/usr/lib/python3.8/urllib/request.py", line 569, in error
    return self._call_chain(*args)
  File "/usr/lib/python3.8/urllib/request.py", line 502, in _call_chain
    result = func(*args)
  File "/usr/lib/python3.8/urllib/request.py", line 649, in http_error_default
    raise HTTPError(req.full_url, code, msg, hdrs, fp)
urllib.error.HTTPError: HTTP Error 404: Not Found

During handling of the above exception, another exception occurred:

Traceback (most recent call last):
  File "main.py", line 23, in <module>
    path_to_zip = keras.utils.get_file("facades.tar.gz", cache_subdir=os.path.abspath(".", ), origin="https://people.eecs.berkeley.edu/~tinghuiz/projects/pix2pix/datasets/facades.tar.gz", extract=True, )
  File "/data/plrg/ve/lib/python3.8/site-packages/tensorflow/python/keras/utils/data_utils.py", line 260, in get_file
    raise Exception(error_msg.format(origin, e.code, e.msg))
Exception: URL fetch failure on https://people.eecs.berkeley.edu/~tinghuiz/projects/pix2pix/datasets/facades.tar.gz: 404 -- Not Found
Traceback (most recent call last):
  File "/data/plrg/ve/lib/python3.8/site-packages/tensorflow/python/keras/utils/data_utils.py", line 258, in get_file
    urlretrieve(origin, fpath, dl_progress)
  File "/usr/lib/python3.8/urllib/request.py", line 247, in urlretrieve
    with contextlib.closing(urlopen(url, data)) as fp:
  File "/usr/lib/python3.8/urllib/request.py", line 222, in urlopen
    return opener.open(url, data, timeout)
  File "/usr/lib/python3.8/urllib/request.py", line 531, in open
    response = meth(req, response)
  File "/usr/lib/python3.8/urllib/request.py", line 640, in http_response
    response = self.parent.error(
  File "/usr/lib/python3.8/urllib/request.py", line 563, in error
    result = self._call_chain(*args)
  File "/usr/lib/python3.8/urllib/request.py", line 502, in _call_chain
    result = func(*args)
  File "/usr/lib/python3.8/urllib/request.py", line 755, in http_error_302
    return self.parent.open(new, timeout=req.timeout)
  File "/usr/lib/python3.8/urllib/request.py", line 531, in open
    response = meth(req, response)
  File "/usr/lib/python3.8/urllib/request.py", line 640, in http_response
    response = self.parent.error(
  File "/usr/lib/python3.8/urllib/request.py", line 569, in error
    return self._call_chain(*args)
  File "/usr/lib/python3.8/urllib/request.py", line 502, in _call_chain
    result = func(*args)
  File "/usr/lib/python3.8/urllib/request.py", line 649, in http_error_default
    raise HTTPError(req.full_url, code, msg, hdrs, fp)
urllib.error.HTTPError: HTTP Error 404: Not Found

During handling of the above exception, another exception occurred:

Traceback (most recent call last):
  File "main.py", line 23, in <module>
    path_to_zip = keras.utils.get_file("facades.tar.gz", cache_subdir=os.path.abspath(".", ), origin="https://people.eecs.berkeley.edu/~tinghuiz/projects/pix2pix/datasets/facades.tar.gz", extract=True, )
  File "/data/plrg/ve/lib/python3.8/site-packages/tensorflow/python/keras/utils/data_utils.py", line 260, in get_file
    raise Exception(error_msg.format(origin, e.code, e.msg))
Exception: URL fetch failure on https://people.eecs.berkeley.edu/~tinghuiz/projects/pix2pix/datasets/facades.tar.gz: 404 -- Not Found
--------------------------------------------------------------------------
Primary job  terminated normally, but 1 process returned
a non-zero exit code. Per user-direction, the job has been aborted.
--------------------------------------------------------------------------
Traceback (most recent call last):
  File "/data/plrg/ve/lib/python3.8/site-packages/tensorflow/python/keras/utils/data_utils.py", line 258, in get_file
    urlretrieve(origin, fpath, dl_progress)
  File "/usr/lib/python3.8/urllib/request.py", line 247, in urlretrieve
    with contextlib.closing(urlopen(url, data)) as fp:
  File "/usr/lib/python3.8/urllib/request.py", line 222, in urlopen
    return opener.open(url, data, timeout)
  File "/usr/lib/python3.8/urllib/request.py", line 531, in open
    response = meth(req, response)
  File "/usr/lib/python3.8/urllib/request.py", line 640, in http_response
    response = self.parent.error(
  File "/usr/lib/python3.8/urllib/request.py", line 563, in error
    result = self._call_chain(*args)
  File "/usr/lib/python3.8/urllib/request.py", line 502, in _call_chain
    result = func(*args)
  File "/usr/lib/python3.8/urllib/request.py", line 755, in http_error_302
    return self.parent.open(new, timeout=req.timeout)
  File "/usr/lib/python3.8/urllib/request.py", line 531, in open
    response = meth(req, response)
  File "/usr/lib/python3.8/urllib/request.py", line 640, in http_response
    response = self.parent.error(
  File "/usr/lib/python3.8/urllib/request.py", line 569, in error
    return self._call_chain(*args)
  File "/usr/lib/python3.8/urllib/request.py", line 502, in _call_chain
    result = func(*args)
  File "/usr/lib/python3.8/urllib/request.py", line 649, in http_error_default
    raise HTTPError(req.full_url, code, msg, hdrs, fp)
urllib.error.HTTPError: HTTP Error 404: Not Found

During handling of the above exception, another exception occurred:

Traceback (most recent call last):
  File "main.py", line 23, in <module>
    path_to_zip = keras.utils.get_file("facades.tar.gz", cache_subdir=os.path.abspath(".", ), origin="https://people.eecs.berkeley.edu/~tinghuiz/projects/pix2pix/datasets/facades.tar.gz", extract=True, )
  File "/data/plrg/ve/lib/python3.8/site-packages/tensorflow/python/keras/utils/data_utils.py", line 260, in get_file
    raise Exception(error_msg.format(origin, e.code, e.msg))
Exception: URL fetch failure on https://people.eecs.berkeley.edu/~tinghuiz/projects/pix2pix/datasets/facades.tar.gz: 404 -- Not Found
--------------------------------------------------------------------------
mpirun detected that one or more processes exited with non-zero status, thus causing
the job to be terminated. The first process to do so was:

  Process name: [[41525,1],2]
  Exit code:    1
--------------------------------------------------------------------------
[dl020:1561780] 3 more processes have sent help message help-mpi-btl-openib.txt / error in device init
[dl020:1561780] Set MCA parameter "orte_base_help_aggregate" to 0 to see all help / error messages
